Workbook
Name Bangladesh_Taxes: '[1]General Assumptions'!$B$8
Name Business_Manager: '[1](BD) Staff'!$D$5
Name ConfSwitch: [2]Assumptions!$C$8
Name Conveyance_Allowance: '[1](BD) Staff'!$D$12
Name costs_per_show: '[1](US) S&M Karima'!$B$58
Name Day_Care_Manager: '[1](BD) Staff'!$D$7
Name Design_Manager: '[1](BD) Staff'!$D$8
Name Festival_Bonus: '[1](BD) Staff'!$D$14
Name Hours_per_Worker_per_Week: '[3]Wage Workers'!$B$7
Name Housing_Allowance: '[1](BD) Staff'!$D$10
Name Housing_Allowance_per_Month: [3]Staff!$C$9
Name HTML_CodePage: 1252
Name HTML_Control: {"'Sheet1'!$A$1:$G$85"}
Name HTML_Description: ""
Name HTML_Email: ""
Name HTML_Header: "Sheet1"
Name HTML_LastUpdate: "2/24/99"
Name HTML_LineAfter: TRUE
Name HTML_LineBefore: TRUE
Name HTML_Name: "Aswath Damodaran"
Name HTML_OBDlg2: TRUE
Name HTML_OBDlg4: TRUE
Name HTML_OS: 1
Name HTML_PathFileMac: "Macintosh HD:HomePageStuff:New_Home_Page:datafile:histret.html"
Name HTML_Title: "Historical Returns on Stocks, Bonds and Bills"
Name HTML1_1: "[ReturnsHistorical]Sheet1!$A$1:$D$77"
Name HTML1_10: ""
Name HTML1_11: 1
Name HTML1_12: "Zip 100:New_Home_Page:datafile:histret.html"
Name HTML1_2: 1
Name HTML1_3: "ReturnsHistorical"
Name HTML1_4: "Historical Returns on Stocks, Bonds and Bills"
Name HTML1_5: "Ibbotson Data"
Name HTML1_6: -4146
Name HTML1_7: -4146
Name HTML1_8: "3/17/97"
Name HTML1_9: "Aswath Damodaran"
Name HTML2_1: "[histret.xls]Sheet1!$A$1:$G$85"
Name HTML2_10: ""
Name HTML2_11: 1
Name HTML2_12: "Macintosh HD:New_Home_Page:datafile:histret.html"
Name HTML2_2: 1
Name HTML2_3: "Historical Returns"
Name HTML2_4: "Historical Returns on Stocks, Bonds and Bills"
Name HTML2_5: ""
Name HTML2_6: 1
Name HTML2_7: 1
Name HTML2_8: "2/3/98"
Name HTML2_9: "Aswath Damodaran"
Name HTMLCount: 2
Name Medical_Cost: '[1](BD) Staff'!$D$13
Name Months_per_Year: [4]Assumptions!$CB$3
Name Production_Manager: '[1](BD) Staff'!$D$6
Name ProjName: '[5]Control Panel'!$D$7
Name Retirement_Allowance: '[1](BD) Staff'!$D$11
Name sale_per_show: '[1](US) S&M Karima'!$B$60
Name solver_cvg: 0.0001
Name solver_drv: 1
Name solver_eng: 1
Name solver_est: 1

Sheet Instructions
B1: Instructions
B3: C-D Model:
B4: 1 | C4: In the C-D Model tab, fill in the formulas in the grids to calculate daily throughput, manufacturing overhead per unit, and manufacturing overhead + materials cost per unit.
B5: 2 | C5: The Cobb-Douglas equation for annual throughput is in the light blue box at the top of the sheet.
B6: 3 | C6: The parameters for A, alpha, and beta for each factory type are listed in the factory parameters boxes at the top of the sheet to the left of the Cobb-Douglas equation.
B7: 4 | C7: The capital (K) and daily labor (Ldaily) inputs for the Cobb-Douglas function are listed in the row and column labels for each grid. Daily labor is referred to as daily expenditure in the simulation.
B8: 5 | C8: Your formulas should reference the factory parameters at the top of the sheet, and the K and L values in each grid's row and column labels.
B9: 6 | C9: The cells highlighted in yellow are intended to contain changeable inputs for your formulas. The values in the other cells should not be changed.
B10: 7 | C10: Rows for values of K that are less than the minimum required capital for a factory type are grayed out.
B11: 8 | C11: You can find more information on the Cobb-Douglas function in the Production section of the Gleacher Game Case Brief posted on Canvas.
B13: Initial Parameters:
B14: 1 | C14: The Initial Parameters tab is included for your convenience. It contains some factory, distribution center, and tax rate parameters for the start of the simulation.
B15: 2 | C15: A more comprehensive summary of simulation parameters can be found in the Quick Reference document posted on Canvas.
B17: Contribution Margin Table:
B18: 1 | C18: The Contribution Margin Table tab contains a template, included here for your convenience, that you can use for calculating contribution margin per unit and per day.

Sheet C-D Model
D4: Bench Factory Parameters | F4: Line Factory Parameters | H4: Cell Factory Parameters | K4: Y = A KαLβ
B5: A | D5: 0.009 | F5: 0.01 | H5: 0.02
B6: α | D6: 0.1 | F6: 0.3 | H6: 0.8
B7: β | D7: =D8-D6 -> 0.85 | F7: 0.75 | H7: 0.3 | K7: Depreciation years | M7: 15
B8: α+β | D8: 0.95 | F8: 1.05 | H8: 1.1
B10: Setup time, in days | D10: 0.05 | F10: 0.5 | H10: 1 | K10: # of days per year | M10: 364
B11: Batch size | D11: 100 | F11: 100 | H11: 100
B13: Minimum capital | D13: 1 | F13: 500000 | H13: 3000000 | K13: Materials cost per unit | M13: 100
C15: Bench | L15: Line | U15: Cell
C17: Daily Throughput in units, including setup time | L17: Daily Throughput in units, including setup time | U17: Daily Throughput in units, including setup time
B18: K ↓ vs Ldaily → | C18: 500 | D18: 1000 | E18: 2500 | F18: 3000 | G18: 4000 | H18: 8000 | I18: 16000 | K18: K ↓ vs Ldaily → | L18: =$C$18 -> 500 | M18: =$D$18 -> 1000 | N18: =$E$18 -> 2500 | O18: =$F$18 -> 3000 | P18: =$G$18 -> 4000 | Q18: =$H$18 -> 8000 | R18: =$I$18 -> 16000 | T18: K ↓ vs Ldaily → | U18: =$C$18 -> 500 | V18: =$D$18 -> 1000 | W18: =$E$18 -> 2500 | X18: =$F$18 -> 3000 | Y18: =$G$18 -> 4000 | Z18: =$H$18 -> 8000 | AA18: =$I$18 -> 16000
B19: 100000 | C19: =$D$11 / ($D$11 / ($D$5 * $B19^$D$6 * (C$18 * $M$10)^$D$7 / $M$10) + $D$10) -> 2.3104672 | D19: =$D$11 / ($D$11 / ($D$5 * $B19^$D$6 * (D$18 * $M$10)^$D$7 / $M$10) + $D$10) -> 4.1607619 | E19: =$D$11 / ($D$11 / ($D$5 * $B19^$D$6 * (E$18 * $M$10)^$D$7 / $M$10) + $D$10) -> 9.0439466 | F19: =$D$11 / ($D$11 / ($D$5 * $B19^$D$6 * (F$18 * $M$10)^$D$7 / $M$10) + $D$10) -> 10.551956 | G19: =$D$11 / ($D$11 / ($D$5 * $B19^$D$6 * (G$18 * $M$10)^$D$7 / $M$10) + $D$10) -> 13.4554 | H19: =$D$11 / ($D$11 / ($D$5 * $B19^$D$6 * (H$18 * $M$10)^$D$7 / $M$10) + $D$10) -> 24.123131 | I19: =$D$11 / ($D$11 / ($D$5 * $B19^$D$6 * (I$18 * $M$10)^$D$7 / $M$10) + $D$10) -> 43.06512 | K19: =$B$19 -> 100000 | L19: N/A | M19: N/A | N19: N/A | O19: N/A | P19: N/A | Q19: N/A | R19: N/A | T19: =$B$19 -> 100000 | U19: N/A | V19: N/A | W19: N/A | X19: N/A | Y19: N/A | Z19: N/A | AA19: N/A
B20: 200000 | C20: =$D$11 / ($D$11 / ($D$5 * $B20^$D$6 * (C$18 * $M$10)^$D$7 / $M$10) + $D$10) -> 2.4760921 | D20: =$D$11 / ($D$11 / ($D$5 * $B20^$D$6 * (D$18 * $M$10)^$D$7 / $M$10) + $D$10) -> 4.4587284 | E20: =$D$11 / ($D$11 / ($D$5 * $B20^$D$6 * (E$18 * $M$10)^$D$7 / $M$10) + $D$10) -> 9.689917 | F20: =$D$11 / ($D$11 / ($D$5 * $B20^$D$6 * (F$18 * $M$10)^$D$7 / $M$10) + $D$10) -> 11.305026 | G20: =$D$11 / ($D$11 / ($D$5 * $B20^$D$6 * (G$18 * $M$10)^$D$7 / $M$10) + $D$10) -> 14.414181 | H20: =$D$11 / ($D$11 / ($D$5 * $B20^$D$6 * (H$18 * $M$10)^$D$7 / $M$10) + $D$10) -> 25.832169 | I20: =$D$11 / ($D$11 / ($D$5 * $B20^$D$6 * (I$18 * $M$10)^$D$7 / $M$10) + $D$10) -> 46.084831 | K20: =$B$20 -> 200000 | L20: N/A | M20: N/A | N20: N/A | O20: N/A | P20: N/A | Q20: N/A | R20: N/A | T20: =$B$20 -> 200000 | U20: N/A | V20: N/A | W20: N/A | X20: N/A | Y20: N/A | Z20: N/A | AA20: N/A
B21: 300000 | C21: =$D$11 / ($D$11 / ($D$5 * $B21^$D$6 * (C$18 * $M$10)^$D$7 / $M$10) + $D$10) -> 2.5784201 | D21: =$D$11 / ($D$11 / ($D$5 * $B21^$D$6 * (D$18 * $M$10)^$D$7 / $M$10) + $D$10) -> 4.6428012 | E21: =$D$11 / ($D$11 / ($D$5 * $B21^$D$6 * (E$18 * $M$10)^$D$7 / $M$10) + $D$10) -> 10.088861 | F21: =$D$11 / ($D$11 / ($D$5 * $B21^$D$6 * (F$18 * $M$10)^$D$7 / $M$10) + $D$10) -> 11.770072 | G21: =$D$11 / ($D$11 / ($D$5 * $B21^$D$6 * (G$18 * $M$10)^$D$7 / $M$10) + $D$10) -> 15.006161 | H21: =$D$11 / ($D$11 / ($D$5 * $B21^$D$6 * (H$18 * $M$10)^$D$7 / $M$10) + $D$10) -> 26.886727 | I21: =$D$11 / ($D$11 / ($D$5 * $B21^$D$6 * (I$18 * $M$10)^$D$7 / $M$10) + $D$10) -> 47.946093 | K21: =$B$21 -> 300000 | L21: N/A | M21: N/A | N21: N/A | O21: N/A | P21: N/A | Q21: N/A | R21: N/A | T21: =$B$21 -> 300000 | U21: N/A | V21: N/A | W21: N/A | X21: N/A | Y21: N/A | Z21: N/A | AA21: N/A
B22: 400000 | C22: =$D$11 / ($D$11 / ($D$5 * $B22^$D$6 * (C$18 * $M$10)^$D$7 / $M$10) + $D$10) -> 2.653574 | D22: =$D$11 / ($D$11 / ($D$5 * $B22^$D$6 * (D$18 * $M$10)^$D$7 / $M$10) + $D$10) -> 4.7779823 | E22: =$D$11 / ($D$11 / ($D$5 * $B22^$D$6 * (E$18 * $M$10)^$D$7 / $M$10) + $D$10) -> 10.381786 | F22: =$D$11 / ($D$11 / ($D$5 * $B22^$D$6 * (F$18 * $M$10)^$D$7 / $M$10) + $D$10) -> 12.111513 | G22: =$D$11 / ($D$11 / ($D$5 * $B22^$D$6 * (G$18 * $M$10)^$D$7 / $M$10) + $D$10) -> 15.440749 | H22: =$D$11 / ($D$11 / ($D$5 * $B22^$D$6 * (H$18 * $M$10)^$D$7 / $M$10) + $D$10) -> 27.66059 | I22: =$D$11 / ($D$11 / ($D$5 * $B22^$D$6 * (I$18 * $M$10)^$D$7 / $M$10) + $D$10) -> 49.310946 | K22: =$B$22 -> 400000 | L22: N/A | M22: N/A | N22: N/A | O22: N/A | P22: N/A | Q22: N/A | R22: N/A | T22: =$B$22 -> 400000 | U22: N/A | V22: N/A | W22: N/A | X22: N/A | Y22: N/A | Z22: N/A | AA22: N/A
B23: 500000 | C23: =$D$11 / ($D$11 / ($D$5 * $B23^$D$6 * (C$18 * $M$10)^$D$7 / $M$10) + $D$10) -> 2.7133712 | D23: =$D$11 / ($D$11 / ($D$5 * $B23^$D$6 * (D$18 * $M$10)^$D$7 / $M$10) + $D$10) -> 4.8855349 | E23: =$D$11 / ($D$11 / ($D$5 * $B23^$D$6 * (E$18 * $M$10)^$D$7 / $M$10) + $D$10) -> 10.614809 | F23: =$D$11 / ($D$11 / ($D$5 * $B23^$D$6 * (F$18 * $M$10)^$D$7 / $M$10) + $D$10) -> 12.383119 | G23: =$D$11 / ($D$11 / ($D$5 * $B23^$D$6 * (G$18 * $M$10)^$D$7 / $M$10) + $D$10) -> 15.786422 | H23: =$D$11 / ($D$11 / ($D$5 * $B23^$D$6 * (H$18 * $M$10)^$D$7 / $M$10) + $D$10) -> 28.275932 | I23: =$D$11 / ($D$11 / ($D$5 * $B23^$D$6 * (I$18 * $M$10)^$D$7 / $M$10) + $D$10) -> 50.395619 | K23: =$B$23 -> 500000 | L23: =$F$11 / ($F$11 / ($F$5 * $K23^$F$6 * (L$18 * $M$10)^$F$7 / $M$10) + $F$10) -> 11.681691 | M23: =$F$11 / ($F$11 / ($F$5 * $K23^$F$6 * (M$18 * $M$10)^$F$7 / $M$10) + $F$10) -> 18.893787 | N23: =$F$11 / ($F$11 / ($F$5 * $K23^$F$6 * (N$18 * $M$10)^$F$7 / $M$10) + $F$10) -> 34.356903 | O23: =$F$11 / ($F$11 / ($F$5 * $K23^$F$6 * (O$18 * $M$10)^$F$7 / $M$10) + $F$10) -> 38.424063 | P23: =$F$11 / ($F$11 / ($F$5 * $K23^$F$6 * (P$18 * $M$10)^$F$7 / $M$10) + $F$10) -> 45.568647 | Q23: =$F$11 / ($F$11 / ($F$5 * $K23^$F$6 * (Q$18 * $M$10)^$F$7 / $M$10) + $F$10) -> 66.332766 | R23: =$F$11 / ($F$11 / ($F$5 * $K23^$F$6 * (R$18 * $M$10)^$F$7 / $M$10) + $F$10) -> 90.984099 | T23: =$B$23 -> 500000 | U23: N/A | V23: N/A | W23: N/A | X23: N/A | Y23: N/A | Z23: N/A | AA23: N/A
B24: 600000 | C24: =$D$11 / ($D$11 / ($D$5 * $B24^$D$6 * (C$18 * $M$10)^$D$7 / $M$10) + $D$10) -> 2.7632265 | D24: =$D$11 / ($D$11 / ($D$5 * $B24^$D$6 * (D$18 * $M$10)^$D$7 / $M$10) + $D$10) -> 4.9752021 | E24: =$D$11 / ($D$11 / ($D$5 * $B24^$D$6 * (E$18 * $M$10)^$D$7 / $M$10) + $D$10) -> 10.80906 | F24: =$D$11 / ($D$11 / ($D$5 * $B24^$D$6 * (F$18 * $M$10)^$D$7 / $M$10) + $D$10) -> 12.609524 | G24: =$D$11 / ($D$11 / ($D$5 * $B24^$D$6 * (G$18 * $M$10)^$D$7 / $M$10) + $D$10) -> 16.074548 | H24: =$D$11 / ($D$11 / ($D$5 * $B24^$D$6 * (H$18 * $M$10)^$D$7 / $M$10) + $D$10) -> 28.788703 | I24: =$D$11 / ($D$11 / ($D$5 * $B24^$D$6 * (I$18 * $M$10)^$D$7 / $M$10) + $D$10) -> 51.299083 | K24: =$B$24 -> 600000 | L24: =$F$11 / ($F$11 / ($F$5 * $K24^$F$6 * (L$18 * $M$10)^$F$7 / $M$10) + $F$10) -> 12.298052 | M24: =$F$11 / ($F$11 / ($F$5 * $K24^$F$6 * (M$18 * $M$10)^$F$7 / $M$10) + $F$10) -> 19.850568 | N24: =$F$11 / ($F$11 / ($F$5 * $K24^$F$6 * (N$18 * $M$10)^$F$7 / $M$10) + $F$10) -> 35.941336 | O24: =$F$11 / ($F$11 / ($F$5 * $K24^$F$6 * (O$18 * $M$10)^$F$7 / $M$10) + $F$10) -> 40.150596 | P24: =$F$11 / ($F$11 / ($F$5 * $K24^$F$6 * (P$18 * $M$10)^$F$7 / $M$10) + $F$10) -> 47.521792 | Q24: =$F$11 / ($F$11 / ($F$5 * $K24^$F$6 * (Q$18 * $M$10)^$F$7 / $M$10) + $F$10) -> 68.779521 | R24: =$F$11 / ($F$11 / ($F$5 * $K24^$F$6 * (R$18 * $M$10)^$F$7 / $M$10) + $F$10) -> 93.702717 | T24: =$B$24 -> 600000 | U24: N/A | V24: N/A | W24: N/A | X24: N/A | Y24: N/A | Z24: N/A | AA24: N/A
B25: 700000 | C25: =$D$11 / ($D$11 / ($D$5 * $B25^$D$6 * (C$18 * $M$10)^$D$7 / $M$10) + $D$10) -> 2.8060916 | D25: =$D$11 / ($D$11 / ($D$5 * $B25^$D$6 * (D$18 * $M$10)^$D$7 / $M$10) + $D$10) -> 5.0522941 | E25: =$D$11 / ($D$11 / ($D$5 * $B25^$D$6 * (E$18 * $M$10)^$D$7 / $M$10) + $D$10) -> 10.976051 | F25: =$D$11 / ($D$11 / ($D$5 * $B25^$D$6 * (F$18 * $M$10)^$D$7 / $M$10) + $D$10) -> 12.804153 | G25: =$D$11 / ($D$11 / ($D$5 * $B25^$D$6 * (G$18 * $M$10)^$D$7 / $M$10) + $D$10) -> 16.32222 | H25: =$D$11 / ($D$11 / ($D$5 * $B25^$D$6 * (H$18 * $M$10)^$D$7 / $M$10) + $D$10) -> 29.229385 | I25: =$D$11 / ($D$11 / ($D$5 * $B25^$D$6 * (I$18 * $M$10)^$D$7 / $M$10) + $D$10) -> 52.075239 | K25: =$B$25 -> 700000 | L25: =$F$11 / ($F$11 / ($F$5 * $K25^$F$6 * (L$18 * $M$10)^$F$7 / $M$10) + $F$10) -> 12.842756 | M25: =$F$11 / ($F$11 / ($F$5 * $K25^$F$6 * (M$18 * $M$10)^$F$7 / $M$10) + $F$10) -> 20.692908 | N25: =$F$11 / ($F$11 / ($F$5 * $K25^$F$6 * (N$18 * $M$10)^$F$7 / $M$10) + $F$10) -> 37.325005 | O25: =$F$11 / ($F$11 / ($F$5 * $K25^$F$6 * (O$18 * $M$10)^$F$7 / $M$10) + $F$10) -> 41.655169 | P25: =$F$11 / ($F$11 / ($F$5 * $K25^$F$6 * (P$18 * $M$10)^$F$7 / $M$10) + $F$10) -> 49.217539 | Q25: =$F$11 / ($F$11 / ($F$5 * $K25^$F$6 * (Q$18 * $M$10)^$F$7 / $M$10) + $F$10) -> 70.881198 | R25: =$F$11 / ($F$11 / ($F$5 * $K25^$F$6 * (R$18 * $M$10)^$F$7 / $M$10) + $F$10) -> 96.008755 | T25: =$B$25 -> 700000 | U25: N/A | V25: N/A | W25: N/A | X25: N/A | Y25: N/A | Z25: N/A | AA25: N/A
B26: 800000 | C26: =$D$11 / ($D$11 / ($D$5 * $B26^$D$6 * (C$18 * $M$10)^$D$7 / $M$10) + $D$10) -> 2.8437594 | D26: =$D$11 / ($D$11 / ($D$5 * $B26^$D$6 * (D$18 * $M$10)^$D$7 / $M$10) + $D$10) -> 5.1200367 | E26: =$D$11 / ($D$11 / ($D$5 * $B26^$D$6 * (E$18 * $M$10)^$D$7 / $M$10) + $D$10) -> 11.122778 | F26: =$D$11 / ($D$11 / ($D$5 * $B26^$D$6 * (F$18 * $M$10)^$D$7 / $M$10) + $D$10) -> 12.975158 | G26: =$D$11 / ($D$11 / ($D$5 * $B26^$D$6 * (G$18 * $M$10)^$D$7 / $M$10) + $D$10) -> 16.53982 | H26: =$D$11 / ($D$11 / ($D$5 * $B26^$D$6 * (H$18 * $M$10)^$D$7 / $M$10) + $D$10) -> 29.616488 | I26: =$D$11 / ($D$11 / ($D$5 * $B26^$D$6 * (I$18 * $M$10)^$D$7 / $M$10) + $D$10) -> 52.756805 | K26: =$B$26 -> 800000 | L26: =$F$11 / ($F$11 / ($F$5 * $K26^$F$6 * (L$18 * $M$10)^$F$7 / $M$10) + $F$10) -> 13.33268 | M26: =$F$11 / ($F$11 / ($F$5 * $K26^$F$6 * (M$18 * $M$10)^$F$7 / $M$10) + $F$10) -> 21.447981 | N26: =$F$11 / ($F$11 / ($F$5 * $K26^$F$6 * (N$18 * $M$10)^$F$7 / $M$10) + $F$10) -> 38.556473 | O26: =$F$11 / ($F$11 / ($F$5 * $K26^$F$6 * (O$18 * $M$10)^$F$7 / $M$10) + $F$10) -> 42.991746 | P26: =$F$11 / ($F$11 / ($F$5 * $K26^$F$6 * (P$18 * $M$10)^$F$7 / $M$10) + $F$10) -> 50.719044 | Q26: =$F$11 / ($F$11 / ($F$5 * $K26^$F$6 * (Q$18 * $M$10)^$F$7 / $M$10) + $F$10) -> 72.724842 | R26: =$F$11 / ($F$11 / ($F$5 * $K26^$F$6 * (R$18 * $M$10)^$F$7 / $M$10) + $F$10) -> 98.009867 | T26: =$B$26 -> 800000 | U26: N/A | V26: N/A | W26: N/A | X26: N/A | Y26: N/A | Z26: N/A | AA26: N/A
B27: 900000 | C27: =$D$11 / ($D$11 / ($D$5 * $B27^$D$6 * (C$18 * $M$10)^$D$7 / $M$10) + $D$10) -> 2.8774036 | D27: =$D$11 / ($D$11 / ($D$5 * $B27^$D$6 * (D$18 * $M$10)^$D$7 / $M$10) + $D$10) -> 5.1805415 | E27: =$D$11 / ($D$11 / ($D$5 * $B27^$D$6 * (E$18 * $M$10)^$D$7 / $M$10) + $D$10) -> 11.253819 | F27: =$D$11 / ($D$11 / ($D$5 * $B27^$D$6 * (F$18 * $M$10)^$D$7 / $M$10) + $D$10) -> 13.127878 | G27: =$D$11 / ($D$11 / ($D$5 * $B27^$D$6 * (G$18 * $M$10)^$D$7 / $M$10) + $D$10) -> 16.734143 | H27: =$D$11 / ($D$11 / ($D$5 * $B27^$D$6 * (H$18 * $M$10)^$D$7 / $M$10) + $D$10) -> 29.962126 | I27: =$D$11 / ($D$11 / ($D$5 * $B27^$D$6 * (I$18 * $M$10)^$D$7 / $M$10) + $D$10) -> 53.365186 | K27: =$B$27 -> 900000 | L27: =$F$11 / ($F$11 / ($F$5 * $K27^$F$6 * (L$18 * $M$10)^$F$7 / $M$10) + $F$10) -> 13.779173 | M27: =$F$11 / ($F$11 / ($F$5 * $K27^$F$6 * (M$18 * $M$10)^$F$7 / $M$10) + $F$10) -> 22.13402 | N27: =$F$11 / ($F$11 / ($F$5 * $K27^$F$6 * (N$18 * $M$10)^$F$7 / $M$10) + $F$10) -> 39.66817 | O27: =$F$11 / ($F$11 / ($F$5 * $K27^$F$6 * (O$18 * $M$10)^$F$7 / $M$10) + $F$10) -> 44.196316 | P27: =$F$11 / ($F$11 / ($F$5 * $K27^$F$6 * (P$18 * $M$10)^$F$7 / $M$10) + $F$10) -> 52.068323 | Q27: =$F$11 / ($F$11 / ($F$5 * $K27^$F$6 * (Q$18 * $M$10)^$F$7 / $M$10) + $F$10) -> 74.3679 | R27: =$F$11 / ($F$11 / ($F$5 * $K27^$F$6 * (R$18 * $M$10)^$F$7 / $M$10) + $F$10) -> 99.77635 | T27: =$B$27 -> 900000 | U27: N/A | V27: N/A | W27: N/A | X27: N/A | Y27: N/A | Z27: N/A | AA27: N/A
B28: 1000000 | C28: =$D$11 / ($D$11 / ($D$5 * $B28^$D$6 * (C$18 * $M$10)^$D$7 / $M$10) + $D$10) -> 2.9078361 | D28: =$D$11 / ($D$11 / ($D$5 * $B28^$D$6 * (D$18 * $M$10)^$D$7 / $M$10) + $D$10) -> 5.2352688 | E28: =$D$11 / ($D$11 / ($D$5 * $B28^$D$6 * (E$18 * $M$10)^$D$7 / $M$10) + $D$10) -> 11.372339 | F28: =$D$11 / ($D$11 / ($D$5 * $B28^$D$6 * (F$18 * $M$10)^$D$7 / $M$10) + $D$10) -> 13.266003 | G28: =$D$11 / ($D$11 / ($D$5 * $B28^$D$6 * (G$18 * $M$10)^$D$7 / $M$10) + $D$10) -> 16.909889 | H28: =$D$11 / ($D$11 / ($D$5 * $B28^$D$6 * (H$18 * $M$10)^$D$7 / $M$10) + $D$10) -> 30.274673 | I28: =$D$11 / ($D$11 / ($D$5 * $B28^$D$6 * (I$18 * $M$10)^$D$7 / $M$10) + $D$10) -> 53.91518 | K28: =$B$28 -> 1000000 | L28: =$F$11 / ($F$11 / ($F$5 * $K28^$F$6 * (L$18 * $M$10)^$F$7 / $M$10) + $F$10) -> 14.190269 | M28: =$F$11 / ($F$11 / ($F$5 * $K28^$F$6 * (M$18 * $M$10)^$F$7 / $M$10) + $F$10) -> 22.763908 | N28: =$F$11 / ($F$11 / ($F$5 * $K28^$F$6 * (N$18 * $M$10)^$F$7 / $M$10) + $F$10) -> 40.682912 | O28: =$F$11 / ($F$11 / ($F$5 * $K28^$F$6 * (O$18 * $M$10)^$F$7 / $M$10) + $F$10) -> 45.294168 | P28: =$F$11 / ($F$11 / ($F$5 * $K28^$F$6 * (P$18 * $M$10)^$F$7 / $M$10) + $F$10) -> 53.294829 | Q28: =$F$11 / ($F$11 / ($F$5 * $K28^$F$6 * (Q$18 * $M$10)^$F$7 / $M$10) + $F$10) -> 75.850356 | R28: =$F$11 / ($F$11 / ($F$5 * $K28^$F$6 * (R$18 * $M$10)^$F$7 / $M$10) + $F$10) -> 101.35667 | T28: =$B$28 -> 1000000 | U28: N/A | V28: N/A | W28: N/A | X28: N/A | Y28: N/A | Z28: N/A | AA28: N/A
B29: 2000000 | C29: =$D$11 / ($D$11 / ($D$5 * $B29^$D$6 * (C$18 * $M$10)^$D$7 / $M$10) + $D$10) -> 3.1162163 | D29: =$D$11 / ($D$11 / ($D$5 * $B29^$D$6 * (D$18 * $M$10)^$D$7 / $M$10) + $D$10) -> 5.6099682 | E29: =$D$11 / ($D$11 / ($D$5 * $B29^$D$6 * (E$18 * $M$10)^$D$7 / $M$10) + $D$10) -> 12.183599 | F29: =$D$11 / ($D$11 / ($D$5 * $B29^$D$6 * (F$18 * $M$10)^$D$7 / $M$10) + $D$10) -> 14.211384 | G29: =$D$11 / ($D$11 / ($D$5 * $B29^$D$6 * (G$18 * $M$10)^$D$7 / $M$10) + $D$10) -> 18.112578 | H29: =$D$11 / ($D$11 / ($D$5 * $B29^$D$6 * (H$18 * $M$10)^$D$7 / $M$10) + $D$10) -> 32.412377 | I29: =$D$11 / ($D$11 / ($D$5 * $B29^$D$6 * (I$18 * $M$10)^$D$7 / $M$10) + $D$10) -> 57.67327 | K29: =$B$29 -> 2000000 | L29: =$F$11 / ($F$11 / ($F$5 * $K29^$F$6 * (L$18 * $M$10)^$F$7 / $M$10) + $F$10) -> 17.18838 | M29: =$F$11 / ($F$11 / ($F$5 * $K29^$F$6 * (M$18 * $M$10)^$F$7 / $M$10) + $F$10) -> 27.307239 | N29: =$F$11 / ($F$11 / ($F$5 * $K29^$F$6 * (N$18 * $M$10)^$F$7 / $M$10) + $F$10) -> 47.837318 | O29: =$F$11 / ($F$11 / ($F$5 * $K29^$F$6 * (O$18 * $M$10)^$F$7 / $M$10) + $F$10) -> 52.989781 | P29: =$F$11 / ($F$11 / ($F$5 * $K29^$F$6 * (P$18 * $M$10)^$F$7 / $M$10) + $F$10) -> 61.806708 | Q29: =$F$11 / ($F$11 / ($F$5 * $K29^$F$6 * (Q$18 * $M$10)^$F$7 / $M$10) + $F$10) -> 85.856404 | R29: =$F$11 / ($F$11 / ($F$5 * $K29^$F$6 * (R$18 * $M$10)^$F$7 / $M$10) + $F$10) -> 111.70013 | T29: =$B$29 -> 2000000 | U29: N/A | V29: N/A | W29: N/A | X29: N/A | Y29: N/A | Z29: N/A | AA29: N/A
B30: 3000000 | C30: =$D$11 / ($D$11 / ($D$5 * $B30^$D$6 * (C$18 * $M$10)^$D$7 / $M$10) + $D$10) -> 3.2449554 | D30: =$D$11 / ($D$11 / ($D$5 * $B30^$D$6 * (D$18 * $M$10)^$D$7 / $M$10) + $D$10) -> 5.8414293 | E30: =$D$11 / ($D$11 / ($D$5 * $B30^$D$6 * (E$18 * $M$10)^$D$7 / $M$10) + $D$10) -> 12.684555 | F30: =$D$11 / ($D$11 / ($D$5 * $B30^$D$6 * (F$18 * $M$10)^$D$7 / $M$10) + $D$10) -> 14.795098 | G30: =$D$11 / ($D$11 / ($D$5 * $B30^$D$6 * (G$18 * $M$10)^$D$7 / $M$10) + $D$10) -> 18.855006 | H30: =$D$11 / ($D$11 / ($D$5 * $B30^$D$6 * (H$18 * $M$10)^$D$7 / $M$10) + $D$10) -> 33.730972 | I30: =$D$11 / ($D$11 / ($D$5 * $B30^$D$6 * (I$18 * $M$10)^$D$7 / $M$10) + $D$10) -> 59.988194 | K30: =$B$30 -> 3000000 | L30: =$F$11 / ($F$11 / ($F$5 * $K30^$F$6 * (L$18 * $M$10)^$F$7 / $M$10) + $F$10) -> 19.198231 | M30: =$F$11 / ($F$11 / ($F$5 * $K30^$F$6 * (M$18 * $M$10)^$F$7 / $M$10) + $F$10) -> 30.304159 | N30: =$F$11 / ($F$11 / ($F$5 * $K30^$F$6 * (N$18 * $M$10)^$F$7 / $M$10) + $F$10) -> 52.403661 | O30: =$F$11 / ($F$11 / ($F$5 * $K30^$F$6 * (O$18 * $M$10)^$F$7 / $M$10) + $F$10) -> 57.860933 | P30: =$F$11 / ($F$11 / ($F$5 * $K30^$F$6 * (P$18 * $M$10)^$F$7 / $M$10) + $F$10) -> 67.118326 | Q30: =$F$11 / ($F$11 / ($F$5 * $K30^$F$6 * (Q$18 * $M$10)^$F$7 / $M$10) + $F$10) -> 91.860966 | R30: =$F$11 / ($F$11 / ($F$5 * $K30^$F$6 * (R$18 * $M$10)^$F$7 / $M$10) + $F$10) -> 117.64919 | T30: =$B$30 -> 3000000 | U30: =$H$11 / ($H$11 / ($H$5 * $T30^$H$6 * (U$18 * $M$10)^$H$7 / $M$10) + $H$10) -> 75.959854 | V30: =$H$11 / ($H$11 / ($H$5 * $T30^$H$6 * (V$18 * $M$10)^$H$7 / $M$10) + $H$10) -> 79.550343 | W30: =$H$11 / ($H$11 / ($H$5 * $T30^$H$6 * (W$18 * $M$10)^$H$7 / $M$10) + $H$10) -> 83.662273 | X30: =$H$11 / ($H$11 / ($H$5 * $T30^$H$6 * (X$18 * $M$10)^$H$7 / $M$10) + $H$10) -> 84.396197 | Y30: =$H$11 / ($H$11 / ($H$5 * $T30^$H$6 * (Y$18 * $M$10)^$H$7 / $M$10) + $H$10) -> 85.499312 | Z30: =$H$11 / ($H$11 / ($H$5 * $T30^$H$6 * (Z$18 * $M$10)^$H$7 / $M$10) + $H$10) -> 87.892149 | AA30: =$H$11 / ($H$11 / ($H$5 * $T30^$H$6 * (AA$18 * $M$10)^$H$7 / $M$10) + $H$10) -> 89.936606
B31: 4000000 | C31: =$D$11 / ($D$11 / ($D$5 * $B31^$D$6 * (C$18 * $M$10)^$D$7 / $M$10) + $D$10) -> 3.3395045 | D31: =$D$11 / ($D$11 / ($D$5 * $B31^$D$6 * (D$18 * $M$10)^$D$7 / $M$10) + $D$10) -> 6.0114048 | E31: =$D$11 / ($D$11 / ($D$5 * $B31^$D$6 * (E$18 * $M$10)^$D$7 / $M$10) + $D$10) -> 13.052351 | F31: =$D$11 / ($D$11 / ($D$5 * $B31^$D$6 * (F$18 * $M$10)^$D$7 / $M$10) + $D$10) -> 15.223621 | G31: =$D$11 / ($D$11 / ($D$5 * $B31^$D$6 * (G$18 * $M$10)^$D$7 / $M$10) + $D$10) -> 19.399971 | H31: =$D$11 / ($D$11 / ($D$5 * $B31^$D$6 * (H$18 * $M$10)^$D$7 / $M$10) + $D$10) -> 34.698365 | I31: =$D$11 / ($D$11 / ($D$5 * $B31^$D$6 * (I$18 * $M$10)^$D$7 / $M$10) + $D$10) -> 61.685011 | K31: =$B$31 -> 4000000 | L31: =$F$11 / ($F$11 / ($F$5 * $K31^$F$6 * (L$18 * $M$10)^$F$7 / $M$10) + $F$10) -> 20.749196 | M31: =$F$11 / ($F$11 / ($F$5 * $K31^$F$6 * (M$18 * $M$10)^$F$7 / $M$10) + $F$10) -> 32.590609 | N31: =$F$11 / ($F$11 / ($F$5 * $K31^$F$6 * (N$18 * $M$10)^$F$7 / $M$10) + $F$10) -> 55.809146 | O31: =$F$11 / ($F$11 / ($F$5 * $K31^$F$6 * (O$18 * $M$10)^$F$7 / $M$10) + $F$10) -> 61.473355 | P31: =$F$11 / ($F$11 / ($F$5 * $K31^$F$6 * (P$18 * $M$10)^$F$7 / $M$10) + $F$10) -> 71.019932 | Q31: =$F$11 / ($F$11 / ($F$5 * $K31^$F$6 * (Q$18 * $M$10)^$F$7 / $M$10) + $F$10) -> 96.160043 | R31: =$F$11 / ($F$11 / ($F$5 * $K31^$F$6 * (R$18 * $M$10)^$F$7 / $M$10) + $F$10) -> 121.79584 | T31: =$B$31 -> 4000000 | U31: =$H$11 / ($H$11 / ($H$5 * $T31^$H$6 * (U$18 * $M$10)^$H$7 / $M$10) + $H$10) -> 79.909143 | V31: =$H$11 / ($H$11 / ($H$5 * $T31^$H$6 * (V$18 * $M$10)^$H$7 / $M$10) + $H$10) -> 83.041476 | W31: =$H$11 / ($H$11 / ($H$5 * $T31^$H$6 * (W$18 * $M$10)^$H$7 / $M$10) + $H$10) -> 86.569936 | X31: =$H$11 / ($H$11 / ($H$5 * $T31^$H$6 * (X$18 * $M$10)^$H$7 / $M$10) + $H$10) -> 87.193236 | Y31: =$H$11 / ($H$11 / ($H$5 * $T31^$H$6 * (Y$18 * $M$10)^$H$7 / $M$10) + $H$10) -> 88.126434 | Z31: =$H$11 / ($H$11 / ($H$5 * $T31^$H$6 * (Z$18 * $M$10)^$H$7 / $M$10) + $H$10) -> 90.135771 | AA31: =$H$11 / ($H$11 / ($H$5 * $T31^$H$6 * (AA$18 * $M$10)^$H$7 / $M$10) + $H$10) -> 91.836571
B32: 5000000 | C32: =$D$11 / ($D$11 / ($D$5 * $B32^$D$6 * (C$18 * $M$10)^$D$7 / $M$10) + $D$10) -> 3.4147324 | D32: =$D$11 / ($D$11 / ($D$5 * $B32^$D$6 * (D$18 * $M$10)^$D$7 / $M$10) + $D$10) -> 6.1466364 | E32: =$D$11 / ($D$11 / ($D$5 * $B32^$D$6 * (E$18 * $M$10)^$D$7 / $M$10) + $D$10) -> 13.344914 | F32: =$D$11 / ($D$11 / ($D$5 * $B32^$D$6 * (F$18 * $M$10)^$D$7 / $M$10) + $D$10) -> 15.564471 | G32: =$D$11 / ($D$11 / ($D$5 * $B32^$D$6 * (G$18 * $M$10)^$D$7 / $M$10) + $D$10) -> 19.833394 | H32: =$D$11 / ($D$11 / ($D$5 * $B32^$D$6 * (H$18 * $M$10)^$D$7 / $M$10) + $D$10) -> 35.467455 | I32: =$D$11 / ($D$11 / ($D$5 * $B32^$D$6 * (I$18 * $M$10)^$D$7 / $M$10) + $D$10) -> 63.033075 | K32: =$B$32 -> 5000000 | L32: =$F$11 / ($F$11 / ($F$5 * $K32^$F$6 * (L$18 * $M$10)^$F$7 / $M$10) + $F$10) -> 22.027539 | M32: =$F$11 / ($F$11 / ($F$5 * $K32^$F$6 * (M$18 * $M$10)^$F$7 / $M$10) + $F$10) -> 34.458249 | N32: =$F$11 / ($F$11 / ($F$5 * $K32^$F$6 * (N$18 * $M$10)^$F$7 / $M$10) + $F$10) -> 58.54206 | O32: =$F$11 / ($F$11 / ($F$5 * $K32^$F$6 * (O$18 * $M$10)^$F$7 / $M$10) + $F$10) -> 64.359834 | P32: =$F$11 / ($F$11 / ($F$5 * $K32^$F$6 * (P$18 * $M$10)^$F$7 / $M$10) + $F$10) -> 74.114842 | Q32: =$F$11 / ($F$11 / ($F$5 * $K32^$F$6 * (Q$18 * $M$10)^$F$7 / $M$10) + $F$10) -> 99.505311 | R32: =$F$11 / ($F$11 / ($F$5 * $K32^$F$6 * (R$18 * $M$10)^$F$7 / $M$10) + $F$10) -> 124.95973 | T32: =$B$32 -> 5000000 | U32: =$H$11 / ($H$11 / ($H$5 * $T32^$H$6 * (U$18 * $M$10)^$H$7 / $M$10) + $H$10) -> 82.622996 | V32: =$H$11 / ($H$11 / ($H$5 * $T32^$H$6 * (V$18 * $M$10)^$H$7 / $M$10) + $H$10) -> 85.409472 | W32: =$H$11 / ($H$11 / ($H$5 * $T32^$H$6 * (W$18 * $M$10)^$H$7 / $M$10) + $H$10) -> 88.513388 | X32: =$H$11 / ($H$11 / ($H$5 * $T32^$H$6 * (X$18 * $M$10)^$H$7 / $M$10) + $H$10) -> 89.057892 | Y32: =$H$11 / ($H$11 / ($H$5 * $T32^$H$6 * (Y$18 * $M$10)^$H$7 / $M$10) + $H$10) -> 89.871001 | Z32: =$H$11 / ($H$11 / ($H$5 * $T32^$H$6 * (Z$18 * $M$10)^$H$7 / $M$10) + $H$10) -> 91.613205 | AA32: =$H$11 / ($H$11 / ($H$5 * $T32^$H$6 * (AA$18 * $M$10)^$H$7 / $M$10) + $H$10) -> 93.078824
C34: Manufacturing Overhead per unit | L34: Manufacturing Overhead per unit | U34: Manufacturing Overhead per unit
B35: K ↓ vs Ldaily → | C35: =$C$18 -> 500 | D35: =$D$18 -> 1000 | E35: =$E$18 -> 2500 | F35: =$F$18 -> 3000 | G35: =$G$18 -> 4000 | H35: =$H$18 -> 8000 | I35: =$I$18 -> 16000 | K35: K ↓ vs Ldaily → | L35: =$C$18 -> 500 | M35: =$D$18 -> 1000 | N35: =$E$18 -> 2500 | O35: =$F$18 -> 3000 | P35: =$G$18 -> 4000 | Q35: =$H$18 -> 8000 | R35: =$I$18 -> 16000 | T35: K ↓ vs Ldaily → | U35: =$C$18 -> 500 | V35: =$D$18 -> 1000 | W35: =$E$18 -> 2500 | X35: =$F$18 -> 3000 | Y35: =$G$18 -> 4000 | Z35: =$H$18 -> 8000 | AA35: =$I$18 -> 16000
B36: =$B$19 -> 100000 | C36: =(C$35 + $B36 / $M$7 / $M$10) / C19 -> 224.33343 | D36: =(D$35 + $B36 / $M$7 / $M$10) / D19 -> 244.74244 | E36: =(E$35 + $B36 / $M$7 / $M$10) / E19 -> 278.45311 | F36: =(F$35 + $B36 / $M$7 / $M$10) / F19 -> 286.04318 | G36: =(G$35 + $B36 / $M$7 / $M$10) / G19 -> 298.63958 | H36: =(H$35 + $B36 / $M$7 / $M$10) / H19 -> 332.39114 | I36: =(I$35 + $B36 / $M$7 / $M$10) / I19 -> 371.95565 | K36: =$B$19 -> 100000 | L36: N/A | M36: N/A | N36: N/A | O36: N/A | P36: N/A | Q36: N/A | R36: N/A | T36: =$B$19 -> 100000 | U36: N/A | V36: N/A | W36: N/A | X36: N/A | Y36: N/A | Z36: N/A | AA36: N/A
B37: =$B$20 -> 200000 | C37: =(C$35 + $B37 / $M$7 / $M$10) / C20 -> 216.72459 | D37: =(D$35 + $B37 / $M$7 / $M$10) / D20 -> 232.49455 | E37: =(E$35 + $B37 / $M$7 / $M$10) / E20 -> 261.78037 | F37: =(F$35 + $B37 / $M$7 / $M$10) / F20 -> 268.60886 | G37: =(G$35 + $B37 / $M$7 / $M$10) / G20 -> 280.04575 | H37: =(H$35 + $B37 / $M$7 / $M$10) / H20 -> 311.10938 | I37: =(I$35 + $B37 / $M$7 / $M$10) / I20 -> 347.98067 | K37: =$B$20 -> 200000 | L37: N/A | M37: N/A | N37: N/A | O37: N/A | P37: N/A | Q37: N/A | R37: N/A | T37: =$B$20 -> 200000 | U37: N/A | V37: N/A | W37: N/A | X37: N/A | Y37: N/A | Z37: N/A | AA37: N/A
B38: =$B$21 -> 300000 | C38: =(C$35 + $B38 / $M$7 / $M$10) / C21 -> 215.22678 | D38: =(D$35 + $B38 / $M$7 / $M$10) / D21 -> 227.22167 | E38: =(E$35 + $B38 / $M$7 / $M$10) / E21 -> 253.24416 | F38: =(F$35 + $B38 / $M$7 / $M$10) / F21 -> 259.55195 | G38: =(G$35 + $B38 / $M$7 / $M$10) / G21 -> 270.21869 | H38: =(H$35 + $B38 / $M$7 / $M$10) / H21 -> 299.58816 | I38: =(I$35 + $B38 / $M$7 / $M$10) / I21 -> 334.85408 | K38: =$B$21 -> 300000 | L38: N/A | M38: N/A | N38: N/A | O38: N/A | P38: N/A | Q38: N/A | R38: N/A | T38: =$B$21 -> 300000 | U38: N/A | V38: N/A | W38: N/A | X38: N/A | Y38: N/A | Z38: N/A | AA38: N/A
B39: =$B$22 -> 400000 | C39: =(C$35 + $B39 / $M$7 / $M$10) / C22 -> 216.0332 | D39: =(D$35 + $B39 / $M$7 / $M$10) / D22 -> 224.62622 | E39: =(E$35 + $B39 / $M$7 / $M$10) / E22 -> 247.86295 | F39: =(F$35 + $B39 / $M$7 / $M$10) / F22 -> 253.747 | G39: =(G$35 + $B39 / $M$7 / $M$10) / G22 -> 263.79938 | H39: =(H$35 + $B39 / $M$7 / $M$10) / H22 -> 291.86868 | I39: =(I$35 + $B39 / $M$7 / $M$10) / I22 -> 325.95724 | K39: =$B$22 -> 400000 | L39: N/A | M39: N/A | N39: N/A | O39: N/A | P39: N/A | Q39: N/A | R39: N/A | T39: =$B$22 -> 400000 | U39: N/A | V39: N/A | W39: N/A | X39: N/A | Y39: N/A | Z39: N/A | AA39: N/A
B40: =$B$23 -> 500000 | C40: =(C$35 + $B40 / $M$7 / $M$10) / C23 -> 218.02218 | D40: =(D$35 + $B40 / $M$7 / $M$10) / D23 -> 223.43 | E40: =(E$35 + $B40 / $M$7 / $M$10) / E23 -> 244.14712 | F40: =(F$35 + $B40 / $M$7 / $M$10) / F23 -> 249.66045 | G40: =(G$35 + $B40 / $M$7 / $M$10) / G23 -> 259.18318 | H40: =(H$35 + $B40 / $M$7 / $M$10) / H23 -> 286.16475 | I40: =(I$35 + $B40 / $M$7 / $M$10) / I23 -> 319.30504 | K40: =$B$23 -> 500000 | L40: =(L$35 + $K40 / $M$7 / $M$10) / L23 -> 50.641221 | M40: =(M$35 + $K40 / $M$7 / $M$10) / M23 -> 57.774289 | N40: =(N$35 + $K40 / $M$7 / $M$10) / N23 -> 75.430987 | O40: =(O$35 + $K40 / $M$7 / $M$10) / O23 -> 80.459349 | P40: =(P$35 + $K40 / $M$7 / $M$10) / P23 -> 89.789261 | Q40: =(Q$35 + $K40 / $M$7 / $M$10) / Q23 -> 121.98459 | R40: =(R$35 + $K40 / $M$7 / $M$10) / R23 -> 176.8614 | T40: =$B$23 -> 500000 | U40: N/A | V40: N/A | W40: N/A | X40: N/A | Y40: N/A | Z40: N/A | AA40: N/A
B41: =$B$24 -> 600000 | C41: =(C$35 + $B41 / $M$7 / $M$10) / C24 -> 220.71665 | D41: =(D$35 + $B41 / $M$7 / $M$10) / D24 -> 223.08443 | E41: =(E$35 + $B41 / $M$7 / $M$10) / E24 -> 241.45395 | F41: =(F$35 + $B41 / $M$7 / $M$10) / F24 -> 246.63025 | G41: =(G$35 + $B41 / $M$7 / $M$10) / G24 -> 255.67687 | H41: =(H$35 + $B41 / $M$7 / $M$10) / H24 -> 281.70391 | I41: =(I$35 + $B41 / $M$7 / $M$10) / I24 -> 314.03856 | K41: =$B$24 -> 600000 | L41: =(L$35 + $K41 / $M$7 / $M$10) / L24 -> 49.592417 | M41: =(M$35 + $K41 / $M$7 / $M$10) / M24 -> 55.91226 | N41: =(N$35 + $K41 / $M$7 / $M$10) / N24 -> 72.615279 | O41: =(O$35 + $K41 / $M$7 / $M$10) / O24 -> 77.45564 | P41: =(P$35 + $K41 / $M$7 / $M$10) / P24 -> 86.484326 | Q41: =(Q$35 + $K41 / $M$7 / $M$10) / Q24 -> 117.91141 | R41: =(R$35 + $K41 / $M$7 / $M$10) / R24 -> 171.92554 | T41: =$B$24 -> 600000 | U41: N/A | V41: N/A | W41: N/A | X41: N/A | Y41: N/A | Z41: N/A | AA41: N/A
B42: =$B$25 -> 700000 | C42: =(C$35 + $B42 / $M$7 / $M$10) / C25 -> 223.87192 | D42: =(D$35 + $B42 / $M$7 / $M$10) / D25 -> 223.30551 | E42: =(E$35 + $B42 / $M$7 / $M$10) / E25 -> 239.44906 | F42: =(F$35 + $B42 / $M$7 / $M$10) / F25 -> 244.31176 | G42: =(G$35 + $B42 / $M$7 / $M$10) / G25 -> 252.91934 | H42: =(H$35 + $B42 / $M$7 / $M$10) / H25 -> 278.08334 | I42: =(I$35 + $B42 / $M$7 / $M$10) / I25 -> 309.70967 | K42: =$B$25 -> 700000 | L42: =(L$35 + $K42 / $M$7 / $M$10) / L25 -> 48.915136 | M42: =(M$35 + $K42 / $M$7 / $M$10) / M25 -> 54.521341 | N42: =(N$35 + $K42 / $M$7 / $M$10) / N25 -> 70.414059 | O42: =(O$35 + $K42 / $M$7 / $M$10) / O25 -> 75.097646 | P42: =(P$35 + $K42 / $M$7 / $M$10) / P25 -> 83.876708 | Q42: =(Q$35 + $K42 / $M$7 / $M$10) / Q25 -> 114.67364 | R42: =(R$35 + $K42 / $M$7 / $M$10) / R25 -> 167.98682 | T42: =$B$25 -> 700000 | U42: N/A | V42: N/A | W42: N/A | X42: N/A | Y42: N/A | Z42: N/A | AA42: N/A
B43: =$B$26 -> 800000 | C43: =(C$35 + $B43 / $M$7 / $M$10) / C26 -> 227.34699 | D43: =(D$35 + $B43 / $M$7 / $M$10) / D26 -> 223.92811 | E43: =(E$35 + $B43 / $M$7 / $M$10) / E26 -> 237.93697 | F43: =(F$35 + $B43 / $M$7 / $M$10) / F26 -> 242.50341 | G43: =(G$35 + $B43 / $M$7 / $M$10) / G26 -> 250.69923 | H43: =(H$35 + $B43 / $M$7 / $M$10) / H26 -> 275.06705 | I43: =(I$35 + $B43 / $M$7 / $M$10) / I26 -> 306.05569 | K43: =$B$26 -> 800000 | L43: =(L$35 + $K43 / $M$7 / $M$10) / L26 -> 48.491388 | M43: =(M$35 + $K43 / $M$7 / $M$10) / M26 -> 53.455854 | N43: =(N$35 + $K43 / $M$7 / $M$10) / N26 -> 68.6401 | O43: =(O$35 + $K43 / $M$7 / $M$10) / O26 -> 73.188936 | P43: =(P$35 + $K43 / $M$7 / $M$10) / P26 -> 81.754699 | Q43: =(Q$35 + $K43 / $M$7 / $M$10) / Q26 -> 112.0184 | R43: =(R$35 + $K43 / $M$7 / $M$10) / R26 -> 164.74382 | T43: =$B$26 -> 800000 | U43: N/A | V43: N/A | W43: N/A | X43: N/A | Y43: N/A | Z43: N/A | AA43: N/A
B44: =$B$27 -> 900000 | C44: =(C$35 + $B44 / $M$7 / $M$10) / C27 -> 231.05384 | D44: =(D$35 + $B44 / $M$7 / $M$10) / D27 -> 224.84815 | E44: =(E$35 + $B44 / $M$7 / $M$10) / E27 -> 236.79385 | F44: =(F$35 + $B44 / $M$7 / $M$10) / F27 -> 241.07743 | G44: =(G$35 + $B44 / $M$7 / $M$10) / G27 -> 248.88248 | H44: =(H$35 + $B44 / $M$7 / $M$10) / H27 -> 272.5052 | I44: =(I$35 + $B44 / $M$7 / $M$10) / I27 -> 302.90975 | K44: =$B$27 -> 900000 | L44: =(L$35 + $K44 / $M$7 / $M$10) / L27 -> 48.249278 | M44: =(M$35 + $K44 / $M$7 / $M$10) / M27 -> 52.626462 | N44: =(N$35 + $K44 / $M$7 / $M$10) / N27 -> 67.178172 | O44: =(O$35 + $K44 / $M$7 / $M$10) / O27 -> 71.608573 | P44: =(P$35 + $K44 / $M$7 / $M$10) / P27 -> 79.987888 | Q44: =(Q$35 + $K44 / $M$7 / $M$10) / Q27 -> 109.78978 | R44: =(R$35 + $K44 / $M$7 / $M$10) / R27 -> 162.01069 | T44: =$B$27 -> 900000 | U44: N/A | V44: N/A | W44: N/A | X44: N/A | Y44: N/A | Z44: N/A | AA44: N/A
B45: =$B$28 -> 1000000 | C45: =(C$35 + $B45 / $M$7 / $M$10) / C28 -> 234.93422 | D45: =(D$35 + $B45 / $M$7 / $M$10) / D28 -> 225.99607 | E45: =(E$35 + $B45 / $M$7 / $M$10) / E28 -> 235.93653 | F45: =(F$35 + $B45 / $M$7 / $M$10) / F28 -> 239.94794 | G45: =(G$35 + $B45 / $M$7 / $M$10) / G28 -> 247.37893 | H45: =(H$35 + $B45 / $M$7 / $M$10) / H28 -> 270.2969 | I45: =(I$35 + $B45 / $M$7 / $M$10) / I28 -> 300.15944 | K45: =$B$28 -> 1000000 | L45: =(L$35 + $K45 / $M$7 / $M$10) / L28 -> 48.14216 | M45: =(M$35 + $K45 / $M$7 / $M$10) / M28 -> 51.974827 | N45: =(N$35 + $K45 / $M$7 / $M$10) / N28 -> 65.952757 | O45: =(O$35 + $K45 / $M$7 / $M$10) / O28 -> 70.277264 | P45: =(P$35 + $K45 / $M$7 / $M$10) / P28 -> 78.490733 | Q45: =(Q$35 + $K45 / $M$7 / $M$10) / Q28 -> 107.88545 | R45: =(R$35 + $K45 / $M$7 / $M$10) / R28 -> 159.66536 | T45: =$B$28 -> 1000000 | U45: N/A | V45: N/A | W45: N/A | X45: N/A | Y45: N/A | Z45: N/A | AA45: N/A
B46: =$B$29 -> 2000000 | C46: =(C$35 + $B46 / $M$7 / $M$10) / C29 -> 277.99751 | D46: =(D$35 + $B46 / $M$7 / $M$10) / D29 -> 243.54868 | E46: =(E$35 + $B46 / $M$7 / $M$10) / E29 -> 235.25893 | F46: =(F$35 + $B46 / $M$7 / $M$10) / F29 -> 236.8735 | G46: =(G$35 + $B46 / $M$7 / $M$10) / G29 -> 241.06454 | H46: =(H$35 + $B46 / $M$7 / $M$10) / H29 -> 258.12055 | I46: =(I$35 + $B46 / $M$7 / $M$10) / I29 -> 283.77618 | K46: =$B$29 -> 2000000 | L46: =(L$35 + $K46 / $M$7 / $M$10) / L29 -> 50.400349 | M46: =(M$35 + $K46 / $M$7 / $M$10) / M29 -> 50.034365 | N46: =(N$35 + $K46 / $M$7 / $M$10) / N29 -> 59.917665 | O46: =(O$35 + $K46 / $M$7 / $M$10) / O29 -> 63.52735 | P46: =(P$35 + $K46 / $M$7 / $M$10) / P29 -> 70.644441 | Q46: =(Q$35 + $K46 / $M$7 / $M$10) / Q29 -> 97.445268 | R46: =(R$35 + $K46 / $M$7 / $M$10) / R29 -> 146.51997 | T46: =$B$29 -> 2000000 | U46: N/A | V46: N/A | W46: N/A | X46: N/A | Y46: N/A | Z46: N/A | AA46: N/A
B47: =$B$30 -> 3000000 | C47: =(C$35 + $B47 / $M$7 / $M$10) / C30 -> 323.40986 | D47: =(D$35 + $B47 / $M$7 / $M$10) / D30 -> 265.25196 | E47: =(E$35 + $B47 / $M$7 / $M$10) / E30 -> 240.40658 | F47: =(F$35 + $B47 / $M$7 / $M$10) / F30 -> 239.90721 | G47: =(G$35 + $B47 / $M$7 / $M$10) / G30 -> 241.28608 | H47: =(H$35 + $B47 / $M$7 / $M$10) / H30 -> 253.45995 | I47: =(I$35 + $B47 / $M$7 / $M$10) / I30 -> 275.87846 | K47: =$B$30 -> 3000000 | L47: =(L$35 + $K47 / $M$7 / $M$10) / L30 -> 54.663919 | M47: =(M$35 + $K47 / $M$7 / $M$10) / M30 -> 51.129964 | N47: =(N$35 + $K47 / $M$7 / $M$10) / N30 -> 58.191556 | O47: =(O$35 + $K47 / $M$7 / $M$10) / O30 -> 61.344509 | P47: =(P$35 + $K47 / $M$7 / $M$10) / P30 -> 67.782539 | Q47: =(Q$35 + $K47 / $M$7 / $M$10) / Q30 -> 93.06946 | R47: =(R$35 + $K47 / $M$7 / $M$10) / R30 -> 140.66779 | T47: =$B$30 -> 3000000 | U47: =(U$35 + $T47 / $M$7 / $M$10) / U30 -> 13.815858 | V47: =(V$35 + $T47 / $M$7 / $M$10) / V30 -> 19.47761 | W47: =(W$35 + $T47 / $M$7 / $M$10) / W30 -> 36.44953 | X47: =(X$35 + $T47 / $M$7 / $M$10) / X30 -> 42.056997 | Y47: =(Y$35 + $T47 / $M$7 / $M$10) / Y30 -> 53.210376 | Z47: =(Z$35 + $T47 / $M$7 / $M$10) / Z30 -> 97.272061 | AA47: =(AA$35 + $T47 / $M$7 / $M$10) / AA30 -> 184.0124
B48: =$B$31 -> 4000000 | C48: =(C$35 + $B48 / $M$7 / $M$10) / C31 -> 369.09689 | D48: =(D$35 + $B48 / $M$7 / $M$10) / D31 -> 288.21894 | E48: =(E$35 + $B48 / $M$7 / $M$10) / E31 -> 247.66425 | F48: =(F$35 + $B48 / $M$7 / $M$10) / F31 -> 245.18482 | G48: =(G$35 + $B48 / $M$7 / $M$10) / G31 -> 243.94886 | H48: =(H$35 + $B48 / $M$7 / $M$10) / H31 -> 251.67182 | I48: =(I$35 + $B48 / $M$7 / $M$10) / I31 -> 271.25878 | K48: =$B$31 -> 4000000 | L48: =(L$35 + $K48 / $M$7 / $M$10) / L31 -> 59.404747 | M48: =(M$35 + $K48 / $M$7 / $M$10) / M31 -> 53.162577 | N48: =(N$35 + $K48 / $M$7 / $M$10) / N31 -> 57.922419 | O48: =(O$35 + $K48 / $M$7 / $M$10) / O31 -> 60.719002 | P48: =(P$35 + $K48 / $M$7 / $M$10) / P31 -> 66.637641 | Q48: =(Q$35 + $K48 / $M$7 / $M$10) / Q31 -> 90.813195 | R48: =(R$35 + $K48 / $M$7 / $M$10) / R31 -> 137.38236 | T48: =$B$31 -> 4000000 | U48: =(U$35 + $T48 / $M$7 / $M$10) / U31 -> 15.425027 | V48: =(V$35 + $T48 / $M$7 / $M$10) / V31 -> 20.864281 | W48: =(W$35 + $T48 / $M$7 / $M$10) / W31 -> 37.340916 | X48: =(X$35 + $T48 / $M$7 / $M$10) / X31 -> 42.808375 | Y48: =(Y$35 + $T48 / $M$7 / $M$10) / Y31 -> 53.702397 | Z48: =(Z$35 + $T48 / $M$7 / $M$10) / Z31 -> 96.882743 | AA48: =(AA$35 + $T48 / $M$7 / $M$10) / AA31 -> 182.19976
...

Sheet Initial Parameters
A1: Initial Factory Parameters
A2: Technology | B2: Bench
A3: K | B3: 100000
A4: Ldaily | B4: $2,500 / day
A5: Batch size | B5: 100 units
A7: Initial Distribution Center Parameters
A8: Heart View Price | B8: $700 / unit
A9: Handling Cost | B9: $10 / unit
A10: Sales Commission | B10: 20% of price
A12: Other
A13: Tax Rate | B13: 0.35

Sheet Contribution Margin Table
B3: Per Unit | C3: Per Day
A4: Revenue | B4: =700 -> 700 | C4: =B4*'C-D Model'!F19 -> 7386.3692
A5: Manufacturing Overhead | B5: ='C-D Model'!F36 -> 286.04318 | C5: =3000+100000/15/364 -> 3018.315
A6: Materials | B6: 100 | C6: =B6*'C-D Model'!F19 -> 1055.1956
A7: Shipping | B7: 20 | C7: =B7*'C-D Model'!F19 -> 211.03912
A8: Handling ($10 per unit) | B8: 10 | C8: =B8*'C-D Model'!F19 -> 105.51956
A9: Commission (20% of revenue) | B9: =B4*0.2 -> 140 | C9: =C4*0.2 -> 1477.2738
A10: Contribution Margin before Tax | B10: =B4-B5-B6-B7-B8-B9 -> 143.95682 | C10: =C4-C5-C6-C7-C8-C9 -> 1519.0261
A11: Tax (35% tax rate) | B11: =B10*0.35 -> 50.384889 | C11: =C10*0.35 -> 531.65913
A12: Contribution Margin after Tax | B12: =B10-B11 -> 93.571936 | C12: =C10-C11 -> 987.36696
A14: Note: Scenario (a) — P=$700, Bench factory K=$100K, L=$2,500/day, batch=100, in-region container shipping ($5K/100 = $50/unit). Throughput = 9.0443 units/day at these parameters.
